<sdf version='1.7'>
  <model name='kmriiwa'>
    <physics type='ode'>
      <max_step_size>0.05</max_step_size>
      <real_time_factor>1.0</real_time_factor>
      <real_time_update_rate>20</real_time_update_rate>
      <sor>1.3</sor>
      <use_dynamic_moi_rescaling>1</use_dynamic_moi_rescaling>      
    </physics>
    <link name='kmriiwa_base_footprint'>
      <inertial>
        <pose>0.004567 -0.002315 0.264696 0 -0 0</pose>
        <mass>397.4</mass>
        <inertia>
          <ixx>30.2884</ixx>
          <ixy>0.61484</ixy>
          <ixz>-0.771926</ixz>
          <iyy>46.2012</iyy>
          <iyz>0.391279</iyz>
          <izz>35.3523</izz>
        </inertia>
      </inertial>
      <collision name='kmriiwa_base_footprint_fixed_joint_lump__kmriiwa_base_link_collision'>
        <pose>0 0 0.025 0 -0 0</pose>
        <geometry>
          <mesh>
            <scale>1 1 1</scale>
            <uri>file:///home/imr/ros2_ws_coresense/install/kmriiwa_description/share/kmriiwa_description/meshes/kmp200/KMP200.dae</uri>
          </mesh>
        </geometry>
        <surface>
          <contact>
            <ode/>
          </contact>
          <friction>
            <ode/>
          </friction>
        </surface>
      </collision>
      <collision name='kmriiwa_base_footprint_fixed_joint_lump__kmriiwa_back_left_wheel_link_collision_1'>
        <pose>-0.28 0.1825 0.125 1.57 -0 0</pose>
        <geometry>
          <cylinder>
            <length>0.132</length>
            <radius>0.125</radius>
          </cylinder>
        </geometry>
        <surface>
          <contact>
            <ode/>
          </contact>
          <friction>
            <ode>
              <mu>0</mu>
              <mu2>0</mu2>
            </ode>
          </friction>
        </surface>
      </collision>
      <collision name='kmriiwa_base_footprint_fixed_joint_lump__kmriiwa_back_right_wheel_link_collision_2'>
        <pose>-0.28 -0.1825 0.125 1.57 -0 0</pose>
        <geometry>
          <cylinder>
            <length>0.132</length>
            <radius>0.125</radius>
          </cylinder>
        </geometry>
        <surface>
          <contact>
            <ode/>
          </contact>
          <friction>
            <ode>
              <mu>0</mu>
              <mu2>0</mu2>
            </ode>
          </friction>
        </surface>
      </collision>
      <collision name='kmriiwa_base_footprint_fixed_joint_lump__kmriiwa_riser_flange_link_collision_3'>
        <pose>0.363 -0.184 0.69 0 0 -1.5708</pose>
        <geometry>
          <cylinder>
            <length>0</length>
            <radius>0</radius>
          </cylinder>
        </geometry>
      </collision>
      <collision name='kmriiwa_base_footprint_fixed_joint_lump__kmriiwa_link_0_collision_4'>
        <pose>0.363 -0.184 0.69 0 0 -1.5708</pose>
        <geometry>
          <mesh>
            <scale>1 1 1</scale>
            <uri>file:///home/imr/ros2_ws_coresense/install/kmriiwa_description/share/kmriiwa_description/meshes/iiwa14/collision/link_0.stl</uri>
          </mesh>
        </geometry>
        <surface>
          <contact>
            <ode/>
          </contact>
          <friction>
            <ode>
              <mu>0.2</mu>
              <mu2>0.2</mu2>
            </ode>
          </friction>
        </surface>
      </collision>
      <collision name='kmriiwa_base_footprint_fixed_joint_lump__kmriiwa_front_left_wheel_link_collision_5'>
        <pose>0.28 0.1825 0.125 1.57 -0 0</pose>
        <geometry>
          <cylinder>
            <length>0.132</length>
            <radius>0.125</radius>
          </cylinder>
        </geometry>
        <surface>
          <contact>
            <ode/>
          </contact>
          <friction>
            <ode>
              <mu>0</mu>
              <mu2>0</mu2>
            </ode>
          </friction>
        </surface>
      </collision>
      <collision name='kmriiwa_base_footprint_fixed_joint_lump__kmriiwa_front_right_wheel_link_collision_6'>
        <pose>0.28 -0.1825 0.125 1.57 -0 0</pose>
        <geometry>
          <cylinder>
            <length>0.132</length>
            <radius>0.125</radius>
          </cylinder>
        </geometry>
        <surface>
          <contact>
            <ode/>
          </contact>
          <friction>
            <ode>
              <mu>0</mu>
              <mu2>0</mu2>
            </ode>
          </friction>
        </surface>
      </collision>
      <collision name='kmriiwa_base_footprint_fixed_joint_lump__kmriiwa_laser_B1_link_collision_7'>
        <pose>0.464 -0.256 0.1418 0 0 -0.7854</pose>
        <geometry>
          <mesh>
            <scale>1 1 1</scale>
            <uri>file:///home/imr/ros2_ws_coresense/install/kmriiwa_description/share/kmriiwa_description/meshes/kmp200/sensors/collision/sick_lms1xx.stl</uri>
          </mesh>
        </geometry>
        <surface>
          <contact>
            <ode/>
          </contact>
          <friction>
            <ode/>
          </friction>
        </surface>
      </collision>
      <collision name='kmriiwa_base_footprint_fixed_joint_lump__kmriiwa_laser_B4_link_collision_8'>
        <pose>-0.464 0.256 0.1418 0 -0 2.3562</pose>
        <geometry>
          <mesh>
            <scale>1 1 1</scale>
            <uri>file:///home/imr/ros2_ws_coresense/install/kmriiwa_description/share/kmriiwa_description/meshes/kmp200/sensors/collision/sick_lms1xx.stl</uri>
          </mesh>
        </geometry>
        <surface>
          <contact>
            <ode/>
          </contact>
          <friction>
            <ode/>
          </friction>
        </surface>
      </collision>
      <visual name='kmriiwa_base_footprint_fixed_joint_lump__kmriiwa_base_link_visual'>
        <pose>0 0 0.025 0 -0 0</pose>
        <geometry>
          <mesh>
            <scale>1 1 1</scale>
            <uri>file:///home/imr/ros2_ws_coresense/install/kmriiwa_description/share/kmriiwa_description/meshes/kmp200/KMP200.dae</uri>
          </mesh>
        </geometry>
        <material>
          <script>
            <name>Gazebo/Grey</name>
            <uri>file://media/materials/scripts/gazebo.material</uri>
          </script>
        </material>
      </visual>
      <visual name='kmriiwa_base_footprint_fixed_joint_lump__kmriiwa_back_left_wheel_link_visual_1'>
        <pose>-0.28 0.1825 0.125 0 -0 0</pose>
        <geometry>
          <mesh>
            <scale>1.06695 1.06695 1.06695</scale>
            <uri>file:///home/imr/ros2_ws_coresense/install/kmriiwa_description/share/kmriiwa_description/meshes/kmp200/wheels/omni_wheel_1.dae</uri>
          </mesh>
        </geometry>
      </visual>
      <visual name='kmriiwa_base_footprint_fixed_joint_lump__kmriiwa_back_right_wheel_link_visual_2'>
        <pose>-0.28 -0.1825 0.125 0 -0 0</pose>
        <geometry>
          <mesh>
            <scale>1.06695 1.06695 1.06695</scale>
            <uri>file:///home/imr/ros2_ws_coresense/install/kmriiwa_description/share/kmriiwa_description/meshes/kmp200/wheels/omni_wheel_1.dae</uri>
          </mesh>
        </geometry>
      </visual>
      <visual name='kmriiwa_base_footprint_fixed_joint_lump__kmriiwa_riser_flange_link_visual_3'>
        <pose>0.363 -0.184 0.69 0 0 -1.5708</pose>
        <geometry>
          <cylinder>
            <length>0</length>
            <radius>0</radius>
          </cylinder>
        </geometry>
      </visual>
      <visual name='kmriiwa_base_footprint_fixed_joint_lump__kmriiwa_link_0_visual_4'>
        <pose>0.363 -0.184 0.69 0 0 -1.5708</pose>
        <geometry>
          <mesh>
            <scale>1 1 1</scale>
            <uri>file:///home/imr/ros2_ws_coresense/install/kmriiwa_description/share/kmriiwa_description/meshes/iiwa14/visual/link_0.stl</uri>
          </mesh>
        </geometry>
        <material>
          <script>
            <name>Gazebo/Grey</name>
            <uri>file://media/materials/scripts/gazebo.material</uri>
          </script>
        </material>
      </visual>
      <visual name='kmriiwa_base_footprint_fixed_joint_lump__kmriiwa_front_left_wheel_link_visual_5'>
        <pose>0.28 0.1825 0.125 0 -0 0</pose>
        <geometry>
          <mesh>
            <scale>1.06695 1.06695 1.06695</scale>
            <uri>file:///home/imr/ros2_ws_coresense/install/kmriiwa_description/share/kmriiwa_description/meshes/kmp200/wheels/omni_wheel_1.dae</uri>
          </mesh>
        </geometry>
      </visual>
      <visual name='kmriiwa_base_footprint_fixed_joint_lump__kmriiwa_front_right_wheel_link_visual_6'>
        <pose>0.28 -0.1825 0.125 0 -0 0</pose>
        <geometry>
          <mesh>
            <scale>1.06695 1.06695 1.06695</scale>
            <uri>file:///home/imr/ros2_ws_coresense/install/kmriiwa_description/share/kmriiwa_description/meshes/kmp200/wheels/omni_wheel_1.dae</uri>
          </mesh>
        </geometry>
      </visual>
      <visual name='kmriiwa_base_footprint_fixed_joint_lump__kmriiwa_laser_B1_link_visual_7'>
        <pose>0.464 -0.256 0.1418 0.0 0.0 -0.7854</pose>
        <geometry>
          <mesh>
            <scale>1 1 1</scale>
            <uri>file:///home/imr/ros2_ws_coresense/install/kmriiwa_description/share/kmriiwa_description/meshes/kmp200/sensors/visual/sick_lms1xx.dae</uri>
          </mesh>
        </geometry>
      </visual>
      <visual name='kmriiwa_base_footprint_fixed_joint_lump__kmriiwa_laser_B4_link_visual_8'>
        <pose>-0.464 0.256 0.1418 0.0 0.0 2.3562</pose>
        <geometry>
          <mesh>
            <scale>1 1 1</scale>
            <uri>file:///home/imr/ros2_ws_coresense/install/kmriiwa_description/share/kmriiwa_description/meshes/kmp200/sensors/visual/sick_lms1xx.dae</uri>
          </mesh>
        </geometry>
      </visual>
      <sensor name='sensor_B1' type='ray'>
        <always_on>1</always_on>
        <visualize>1</visualize>
        <update_rate>20</update_rate>
        <ray>
          <scan>
            <horizontal>
              <samples>320</samples>
              <resolution>1</resolution>
              <min_angle>-2.3562</min_angle>
              <max_angle>0.9853</max_angle>
            </horizontal>
          </scan>
          <range>
            <min>0.3</min>
            <max>10</max>
            <resolution>0.01</resolution>
          </range>
          <noise>
            <type>gaussian</type>
            <mean>0</mean>
            <stddev>0.01</stddev>
          </noise>
        </ray>
        <plugin name='gazebo_sensor_B1_controller' filename='libgazebo_ros_ray_sensor.so'>
        <ros>          
          <remapping>~/out:=/kmriiwa/base/state/LaserB1Scan</remapping>
        </ros>
          <output_type>sensor_msgs/LaserScan</output_type>
          <frameName>kmriiwa_laser_B1_link</frameName>
        </plugin>
        <pose>0.464 -0.256 0.1418 0 0 0.0</pose>
      </sensor>
      <sensor name='sensor_B4' type='ray'>
        <always_on>1</always_on>
        <visualize>1</visualize>
        <update_rate>20</update_rate>
        <ray>
          <scan>
            <horizontal>
              <samples>240</samples>
              <resolution>1</resolution>
              <min_angle>0.7853</min_angle>
              <max_angle>3.6268</max_angle>
            </horizontal>
          </scan>
          <range>
            <min>0.3</min>
            <max>10</max>
            <resolution>0.01</resolution>
          </range>
          <noise>
            <type>gaussian</type>
            <mean>0</mean>
            <stddev>0.01</stddev>
          </noise>
        </ray>
        <plugin name='gazebo_sensor_B4_controller' filename='libgazebo_ros_ray_sensor.so'>
        <ros>          
          <remapping>~/out:=/kmriiwa/base/state/LaserB4Scan</remapping>
        </ros>
          <output_type>sensor_msgs/LaserScan</output_type>
          <frameName>kmriiwa_laser_B4_link</frameName>
        </plugin>
        <pose>-0.464 0.256 0.1418 0.0 0.0 0.0</pose>
      </sensor>
      <surface>
        <contact>
          <collide_without_contact>1</collide_without_contact>
        </contact>
      </surface>
      <surface>
        <contact>
          <collide_without_contact>1</collide_without_contact>
        </contact>
      </surface>
      <surface>
        <contact>
          <collide_without_contact>1</collide_without_contact>
        </contact>
      </surface>
      <surface>
        <contact>
          <collide_without_contact>1</collide_without_contact>
        </contact>
      </surface>
    </link>
    <joint name='kmriiwa_joint_1' type='revolute'>
      <pose relative_to='kmriiwa_base_footprint'>0.363 -0.184 0.8475 0 0 -1.5708</pose>
      <parent>kmriiwa_base_footprint</parent>
      <child>kmriiwa_link_1</child>
      <axis>
        <xyz>0 0 1</xyz>
        <limit>
          <lower>-2.96706</lower>
          <upper>2.96706</upper>
          <effort>300</effort>
          <velocity>10</velocity>
        </limit>
        <dynamics>
          <damping>0.5</damping>
          <friction>0</friction>
          <spring_reference>0</spring_reference>
          <spring_stiffness>0</spring_stiffness>
        </dynamics>
      </axis>
    </joint>
    <link name='kmriiwa_link_1'>
    <gravity>0</gravity>
      <pose relative_to='kmriiwa_joint_1'>0 0 0 0 -0 0</pose>
      <inertial>
        <pose>0 -0.03 0.12 0 -0 0</pose>
        <mass>4</mass>
        <inertia>
          <ixx>0.1</ixx>
          <ixy>0</ixy>
          <ixz>0</ixz>
          <iyy>0.09</iyy>
          <iyz>0</iyz>
          <izz>0.02</izz>
        </inertia>
      </inertial>
      <collision name='kmriiwa_link_1_collision'>
        <pose>0 0 0 0 -0 0</pose>
        <geometry>
          <mesh>
            <scale>1 1 1</scale>
            <uri>file:///home/imr/ros2_ws_coresense/install/kmriiwa_description/share/kmriiwa_description/meshes/iiwa14/collision/link_1.stl</uri>
          </mesh>
        </geometry>
        <surface>
          <contact>
            <ode/>
          </contact>
          <friction>
            <ode>
              <mu>0.2</mu>
              <mu2>0.2</mu2>
            </ode>
          </friction>
        </surface>
      </collision>
      <visual name='kmriiwa_link_1_visual'>
        <pose>0 0 0 0 -0 0</pose>
        <geometry>
          <mesh>
            <scale>1 1 1</scale>
            <uri>file:///home/imr/ros2_ws_coresense/install/kmriiwa_description/share/kmriiwa_description/meshes/iiwa14/visual/link_1.stl</uri>
          </mesh>
        </geometry>
        <material>
          <script>
            <name>Gazebo/Orange</name>
            <uri>file://media/materials/scripts/gazebo.material</uri>
          </script>
        </material>
      </visual>
    </link>
    <joint name='kmriiwa_joint_2' type='revolute'>
      <pose relative_to='kmriiwa_link_1'>0 0 0.2025 1.5708 -0 3.14159</pose>
      <parent>kmriiwa_link_1</parent>
      <child>kmriiwa_link_2</child>
      <axis>
        <xyz>0 0 1</xyz>
        <limit>
          <lower>-2.0944</lower>
          <upper>2.0944</upper>
          <effort>300</effort>
          <velocity>10</velocity>
        </limit>
        <dynamics>
          <damping>0.5</damping>
          <friction>0</friction>
          <spring_reference>0</spring_reference>
          <spring_stiffness>0</spring_stiffness>
        </dynamics>
      </axis>
    </joint>
    <link name='kmriiwa_link_2'>
    <gravity>0</gravity>
      <pose relative_to='kmriiwa_joint_2'>0 0 0 0 -0 0</pose>
      <inertial>
        <pose>0.0003 0.059 0.042 0 -0 0</pose>
        <mass>4</mass>
        <inertia>
          <ixx>0.05</ixx>
          <ixy>0</ixy>
          <ixz>0</ixz>
          <iyy>0.018</iyy>
          <iyz>0</iyz>
          <izz>0.044</izz>
        </inertia>
      </inertial>
      <collision name='kmriiwa_link_2_collision'>
        <pose>0 0 0 0 -0 0</pose>
        <geometry>
          <mesh>
            <scale>1 1 1</scale>
            <uri>file:///home/imr/ros2_ws_coresense/install/kmriiwa_description/share/kmriiwa_description/meshes/iiwa14/collision/link_2.stl</uri>
          </mesh>
        </geometry>
        <surface>
          <contact>
            <ode/>
          </contact>
          <friction>
            <ode>
              <mu>0.2</mu>
              <mu2>0.2</mu2>
            </ode>
          </friction>
        </surface>
      </collision>
      <visual name='kmriiwa_link_2_visual'>
        <pose>0 0 0 0 -0 0</pose>
        <geometry>
          <mesh>
            <scale>1 1 1</scale>
            <uri>file:///home/imr/ros2_ws_coresense/install/kmriiwa_description/share/kmriiwa_description/meshes/iiwa14/visual/link_2.stl</uri>
          </mesh>
        </geometry>
        <material>
          <script>
            <name>Gazebo/Orange</name>
            <uri>file://media/materials/scripts/gazebo.material</uri>
          </script>
        </material>
      </visual>
    </link>
    <joint name='kmriiwa_joint_3' type='revolute'>
      <pose relative_to='kmriiwa_link_2'>0 0.2045 0 1.5708 -0 3.14159</pose>
      <parent>kmriiwa_link_2</parent>
      <child>kmriiwa_link_3</child>
      <axis>
        <xyz>0 0 1</xyz>
        <limit>
          <lower>-2.96706</lower>
          <upper>2.96706</upper>
          <effort>300</effort>
          <velocity>10</velocity>
        </limit>
        <dynamics>
          <damping>0.5</damping>
          <friction>0</friction>
          <spring_reference>0</spring_reference>
          <spring_stiffness>0</spring_stiffness>
        </dynamics>
      </axis>
    </joint>
    <link name='kmriiwa_link_3'>
    <gravity>0</gravity>
      <pose relative_to='kmriiwa_joint_3'>0 0 0 0 -0 0</pose>
      <inertial>
        <pose>0 0.03 0.13 0 -0 0</pose>
        <mass>3</mass>
        <inertia>
          <ixx>0.08</ixx>
          <ixy>0</ixy>
          <ixz>0</ixz>
          <iyy>0.075</iyy>
          <iyz>0</iyz>
          <izz>0.01</izz>
        </inertia>
      </inertial>
      <collision name='kmriiwa_link_3_collision'>
        <pose>0 0 0 0 -0 0</pose>
        <geometry>
          <mesh>
            <scale>1 1 1</scale>
            <uri>file:///home/imr/ros2_ws_coresense/install/kmriiwa_description/share/kmriiwa_description/meshes/iiwa14/collision/link_3.stl</uri>
          </mesh>
        </geometry>
        <surface>
          <contact>
            <ode/>
          </contact>
          <friction>
            <ode>
              <mu>0.2</mu>
              <mu2>0.2</mu2>
            </ode>
          </friction>
        </surface>
      </collision>
      <visual name='kmriiwa_link_3_visual'>
        <pose>0 0 0 0 -0 0</pose>
        <geometry>
          <mesh>
            <scale>1 1 1</scale>
            <uri>file:///home/imr/ros2_ws_coresense/install/kmriiwa_description/share/kmriiwa_description/meshes/iiwa14/visual/link_3.stl</uri>
          </mesh>
        </geometry>
        <material>
          <script>
            <name>Gazebo/Orange</name>
            <uri>file://media/materials/scripts/gazebo.material</uri>
          </script>
        </material>
      </visual>
    </link>
    <joint name='kmriiwa_joint_4' type='revolute'>
      <pose relative_to='kmriiwa_link_3'>0 0 0.2155 1.5708 -0 0</pose>
      <parent>kmriiwa_link_3</parent>
      <child>kmriiwa_link_4</child>
      <axis>
        <xyz>0 0 1</xyz>
        <limit>
          <lower>-2.0944</lower>
          <upper>2.0944</upper>
          <effort>300</effort>
          <velocity>10</velocity>
        </limit>
        <dynamics>
          <damping>0.5</damping>
          <friction>0</friction>
          <spring_reference>0</spring_reference>
          <spring_stiffness>0</spring_stiffness>
        </dynamics>
      </axis>
    </joint>
    <link name='kmriiwa_link_4'>
    <gravity>0</gravity>
      <pose relative_to='kmriiwa_joint_4'>0 0 0 0 -0 0</pose>
      <inertial>
        <pose>0 0.067 0.034 0 -0 0</pose>
        <mass>2.7</mass>
        <inertia>
          <ixx>0.03</ixx>
          <ixy>0</ixy>
          <ixz>0</ixz>
          <iyy>0.01</iyy>
          <iyz>0</iyz>
          <izz>0.029</izz>
        </inertia>
      </inertial>
      <collision name='kmriiwa_link_4_collision'>
        <pose>0 0 0 0 -0 0</pose>
        <geometry>
          <mesh>
            <scale>1 1 1</scale>
            <uri>file:///home/imr/ros2_ws_coresense/install/kmriiwa_description/share/kmriiwa_description/meshes/iiwa14/collision/link_4.stl</uri>
          </mesh>
        </geometry>
        <surface>
          <contact>
            <ode/>
          </contact>
          <friction>
            <ode>
              <mu>0.2</mu>
              <mu2>0.2</mu2>
            </ode>
          </friction>
        </surface>
      </collision>
      <visual name='kmriiwa_link_4_visual'>
        <pose>0 0 0 0 -0 0</pose>
        <geometry>
          <mesh>
            <scale>1 1 1</scale>
            <uri>file:///home/imr/ros2_ws_coresense/install/kmriiwa_description/share/kmriiwa_description/meshes/iiwa14/visual/link_4.stl</uri>
          </mesh>
        </geometry>
        <material>
          <script>
            <name>Gazebo/Orange</name>
            <uri>file://media/materials/scripts/gazebo.material</uri>
          </script>
        </material>
      </visual>
    </link>
    <joint name='kmriiwa_joint_5' type='revolute'>
      <pose relative_to='kmriiwa_link_4'>0 0.1845 0 1.5708 0 3.14159</pose>
      <parent>kmriiwa_link_4</parent>
      <child>kmriiwa_link_5</child>
      <axis>
        <xyz>0 0 1</xyz>
        <limit>
          <lower>-2.96706</lower>
          <upper>2.96706</upper>
          <effort>300</effort>
          <velocity>10</velocity>
        </limit>
        <dynamics>
          <damping>0.5</damping>
          <friction>0</friction>
          <spring_reference>0</spring_reference>
          <spring_stiffness>0</spring_stiffness>
        </dynamics>
      </axis>
    </joint>
    <link name='kmriiwa_link_5'>
      <gravity>0</gravity>
      <pose relative_to='kmriiwa_joint_5'>0 0 0 0 -0 0</pose>
      <inertial>
        <pose>0.0001 0.021 0.076 0 -0 0</pose>
        <mass>1.7</mass>
        <inertia>
          <ixx>0.02</ixx>
          <ixy>0</ixy>
          <ixz>0</ixz>
          <iyy>0.018</iyy>
          <iyz>0</iyz>
          <izz>0.005</izz>
        </inertia>
      </inertial>
      <collision name='kmriiwa_link_5_collision'>
        <pose>0 0 0 0 -0 0</pose>
        <geometry>
          <mesh>
            <scale>1 1 1</scale>
            <uri>file:///home/imr/ros2_ws_coresense/install/kmriiwa_description/share/kmriiwa_description/meshes/iiwa14/collision/link_5.stl</uri>
          </mesh>
        </geometry>
        <surface>
          <contact>
            <ode/>
          </contact>
          <friction>
            <ode>
              <mu>0.2</mu>
              <mu2>0.2</mu2>
            </ode>
          </friction>
        </surface>
      </collision>
      <visual name='kmriiwa_link_5_visual'>
        <pose>0 0 0 0 -0 0</pose>
        <geometry>
          <mesh>
            <scale>1 1 1</scale>
            <uri>file:///home/imr/ros2_ws_coresense/install/kmriiwa_description/share/kmriiwa_description/meshes/iiwa14/visual/link_5.stl</uri>
          </mesh>
        </geometry>
        <material>
          <script>
            <name>Gazebo/Orange</name>
            <uri>file://media/materials/scripts/gazebo.material</uri>
          </script>
        </material>
      </visual>
    </link>
    <joint name='kmriiwa_joint_6' type='revolute'>
      <pose relative_to='kmriiwa_link_5'>0 0 0.2155 1.5708 -0 0</pose>
      <parent>kmriiwa_link_5</parent>
      <child>kmriiwa_link_6</child>
      <axis>
        <xyz>0 0 1</xyz>
        <limit>
          <lower>-2.0944</lower>
          <upper>2.0944</upper>
          <effort>300</effort>
          <velocity>10</velocity>
        </limit>
        <dynamics>
          <damping>0.5</damping>
          <friction>0</friction>
          <spring_reference>0</spring_reference>
          <spring_stiffness>0</spring_stiffness>
        </dynamics>
      </axis>
    </joint>
    <link name='kmriiwa_link_6'>
      <gravity>0</gravity>
      <pose relative_to='kmriiwa_joint_6'>0 0 0 0 -0 0</pose>
      <inertial>
        <pose>0 0.0006 0.0004 0 -0 0</pose>
        <mass>1.8</mass>
        <inertia>
          <ixx>0.005</ixx>
          <ixy>0</ixy>
          <ixz>0</ixz>
          <iyy>0.0036</iyy>
          <iyz>0</iyz>
          <izz>0.0047</izz>
        </inertia>
      </inertial>
      <collision name='kmriiwa_link_6_collision'>
        <pose>0 0 0 0 -0 0</pose>
        <geometry>
          <mesh>
            <scale>1 1 1</scale>
            <uri>file:///home/imr/ros2_ws_coresense/install/kmriiwa_description/share/kmriiwa_description/meshes/iiwa14/collision/link_6.stl</uri>
          </mesh>
        </geometry>
        <surface>
          <contact>
            <ode/>
          </contact>
          <friction>
            <ode>
              <mu>0.2</mu>
              <mu2>0.2</mu2>
            </ode>
          </friction>
        </surface>
      </collision>
      <visual name='kmriiwa_link_6_visual'>
        <pose>0 0 0 0 -0 0</pose>
        <geometry>
          <mesh>
            <scale>1 1 1</scale>
            <uri>file:///home/imr/ros2_ws_coresense/install/kmriiwa_description/share/kmriiwa_description/meshes/iiwa14/visual/link_6.stl</uri>
          </mesh>
        </geometry>
        <material>
          <script>
            <name>Gazebo/Orange</name>
            <uri>file://media/materials/scripts/gazebo.material</uri>
          </script>
        </material>
      </visual>
    </link>
    <joint name='kmriiwa_joint_7' type='revolute'>
      <pose relative_to='kmriiwa_link_6'>0 0.081 0 1.5708 0 3.14159</pose>
      <parent>kmriiwa_link_6</parent>
      <child>kmriiwa_link_7</child>
      <axis>
        <xyz>0 0 1</xyz>
        <limit>
          <lower>-3.05433</lower>
          <upper>3.05433</upper>
          <effort>300</effort>
          <velocity>10</velocity>
        </limit>
        <dynamics>
          <damping>0.5</damping>
          <friction>0</friction>
          <spring_reference>0</spring_reference>
          <spring_stiffness>0</spring_stiffness>
        </dynamics>
      </axis>
      <physics type='ode'>
        <!-- Other physics parameters -->
        <real_time_update_rate>1000</real_time_update_rate>
	<max_step_size>0.001</max_step_size>
	<real_time_factor>1.0</real_time_factor>
        <ode>
          <solver>
            <type>quick</type>
            <iters>50</iters>
            <sor>1.3</sor>
          </solver>
          <constraints>
            <cfm>0</cfm>
            <erp>0.2</erp>
            <contact_max_correcting_vel>100</contact_max_correcting_vel>
            <contact_surface_layer>0.001</contact_surface_layer>
          </constraints>
        </ode>
      </physics>
    </joint>
    <link name='kmriiwa_link_7'>
      <gravity>0</gravity>
      <pose relative_to='kmriiwa_joint_7'>0 0 0 0 -0 0</pose>
      <inertial>
        <pose>0 0 0.02 0 -0 0</pose>
        <mass>0.3</mass>
        <inertia>
          <ixx>0.001</ixx>
          <ixy>0</ixy>
          <ixz>0</ixz>
          <iyy>0.001</iyy>
          <iyz>0</iyz>
          <izz>0.001</izz>
        </inertia>
      </inertial>
      <collision name='kmriiwa_link_7_collision'>
        <pose>0 0 0 0 -0 0</pose>
        <geometry>
          <mesh>
            <scale>1 1 1</scale>
            <uri>file:///home/imr/ros2_ws_coresense/install/kmriiwa_description/share/kmriiwa_description/meshes/iiwa14/collision/link_7.stl</uri>
          </mesh>
        </geometry>
        <surface>
          <contact>
            <ode/>
          </contact>
          <friction>
            <ode>
              <mu>0.2</mu>
              <mu2>0.2</mu2>
            </ode>
          </friction>
        </surface>
      </collision>
      <visual name='kmriiwa_link_7_visual'>
        <pose>0 0 0 0 -0 0</pose>
        <geometry>
          <mesh>
            <scale>1 1 1</scale>
            <uri>file:///home/imr/ros2_ws_coresense/install/kmriiwa_description/share/kmriiwa_description/meshes/iiwa14/visual/link_7.stl</uri>
          </mesh>
        </geometry>
        <material>
          <script>
            <name>Gazebo/Grey</name>
            <uri>file://media/materials/scripts/gazebo.material</uri>
          </script>
        </material>
      </visual>
    </link>
    <plugin name='planar_move' filename='libgazebo_ros_planar_move.so'>
        <ros>
          <!--<argument>--ros-args --remap cmd_vel:=cmd_vel</argument>-->
          <!--<argument>--ros-args --remap kmriiwa_odom:=odom</argument>-->
          <!--<remapping>cmd_vel:=/kmriiwa/base/cmd_vel</remapping>-->
          <!--<remapping>odom:=kmriiwa_odom</remapping>-->
        </ros>

        <update_rate>20</update_rate>
        <publish_rate>20</publish_rate>

        <!-- output -->
        <publish_odom>true</publish_odom>
        <publish_odom_tf>true</publish_odom_tf>

        <odometry_frame>kmriiwa_odom</odometry_frame>
        <robot_base_frame>kmriiwa_base_footprint</robot_base_frame>

        <covariance_x>0.0001</covariance_x>
        <covariance_y>0.0001</covariance_y>
        <covariance_yaw>0.01</covariance_yaw>
    </plugin>
    <plugin name="gazebo_ros_joint_state_publisher" filename="libgazebo_ros_joint_state_publisher.so">
      <ros>
        <!-- <namespace>/kmriiwa</namespace> -->
        <argument>--ros-args --remap ~/out:=/kmriiwa/arm/joint_states</argument>
      </ros>
      <update_rate>20</update_rate>
      <joint_name>kmriiwa_joint_1</joint_name>
      <joint_name>kmriiwa_joint_2</joint_name>
      <joint_name>kmriiwa_joint_3</joint_name>
      <joint_name>kmriiwa_joint_4</joint_name>
      <joint_name>kmriiwa_joint_5</joint_name>
      <joint_name>kmriiwa_joint_6</joint_name>
      <joint_name>kmriiwa_joint_7</joint_name>

    </plugin>
    <!--<static>0</static>   --> 
  </model>
</sdf>
